2022-09-07 11:30:30,114 ERROR: Exception on /register [POST] [in /usr/local/lib/python3.9/site-packages/flask/app.py:1457]
Traceback (most recent call last):
  File "/usr/local/lib/python3.9/site-packages/sqlalchemy/engine/base.py", line 1808, in _execute_context
    self.dialect.do_execute(
  File "/usr/local/lib/python3.9/site-packages/sqlalchemy/engine/default.py", line 732, in do_execute
    cursor.execute(statement, parameters)
  File "/usr/local/lib/python3.9/site-packages/pymysql/cursors.py", line 148, in execute
    result = self._query(query)
  File "/usr/local/lib/python3.9/site-packages/pymysql/cursors.py", line 310, in _query
    conn.query(q)
  File "/usr/local/lib/python3.9/site-packages/pymysql/connections.py", line 548, in query
    self._affected_rows = self._read_query_result(unbuffered=unbuffered)
  File "/usr/local/lib/python3.9/site-packages/pymysql/connections.py", line 775, in _read_query_result
    result.read()
  File "/usr/local/lib/python3.9/site-packages/pymysql/connections.py", line 1156, in read
    first_packet = self.connection._read_packet()
  File "/usr/local/lib/python3.9/site-packages/pymysql/connections.py", line 725, in _read_packet
    packet.raise_for_error()
  File "/usr/local/lib/python3.9/site-packages/pymysql/protocol.py", line 221, in raise_for_error
    err.raise_mysql_exception(self._data)
  File "/usr/local/lib/python3.9/site-packages/pymysql/err.py", line 143, in raise_mysql_exception
    raise errorclass(errno, errval)
pymysql.err.IntegrityError: (1062, "Duplicate entry 'Testing@dtswiss.com' for key 'ix_user_email'")

The above exception was the direct cause of the following exception:

Traceback (most recent call last):
  File "/usr/local/lib/python3.9/site-packages/flask/app.py", line 2073, in wsgi_app
    response = self.full_dispatch_request()
  File "/usr/local/lib/python3.9/site-packages/flask/app.py", line 1518, in full_dispatch_request
    rv = self.handle_user_exception(e)
  File "/usr/local/lib/python3.9/site-packages/flask/app.py", line 1516, in full_dispatch_request
    rv = self.dispatch_request()
  File "/usr/local/lib/python3.9/site-packages/flask/app.py", line 1502, in dispatch_request
    return self.ensure_sync(self.view_functions[rule.endpoint])(**req.view_args)
  File "/app/app/routes.py", line 82, in register
    db.session.commit()
  File "<string>", line 2, in commit
  File "/usr/local/lib/python3.9/site-packages/sqlalchemy/orm/session.py", line 1431, in commit
    self._transaction.commit(_to_root=self.future)
  File "/usr/local/lib/python3.9/site-packages/sqlalchemy/orm/session.py", line 829, in commit
    self._prepare_impl()
  File "/usr/local/lib/python3.9/site-packages/sqlalchemy/orm/session.py", line 808, in _prepare_impl
    self.session.flush()
  File "/usr/local/lib/python3.9/site-packages/sqlalchemy/orm/session.py", line 3363, in flush
    self._flush(objects)
  File "/usr/local/lib/python3.9/site-packages/sqlalchemy/orm/session.py", line 3503, in _flush
    transaction.rollback(_capture_exception=True)
  File "/usr/local/lib/python3.9/site-packages/sqlalchemy/util/langhelpers.py", line 70, in __exit__
    compat.raise_(
  File "/usr/local/lib/python3.9/site-packages/sqlalchemy/util/compat.py", line 207, in raise_
    raise exception
  File "/usr/local/lib/python3.9/site-packages/sqlalchemy/orm/session.py", line 3463, in _flush
    flush_context.execute()
  File "/usr/local/lib/python3.9/site-packages/sqlalchemy/orm/unitofwork.py", line 456, in execute
    rec.execute(self)
  File "/usr/local/lib/python3.9/site-packages/sqlalchemy/orm/unitofwork.py", line 630, in execute
    util.preloaded.orm_persistence.save_obj(
  File "/usr/local/lib/python3.9/site-packages/sqlalchemy/orm/persistence.py", line 244, in save_obj
    _emit_insert_statements(
  File "/usr/local/lib/python3.9/site-packages/sqlalchemy/orm/persistence.py", line 1237, in _emit_insert_statements
    result = connection._execute_20(
  File "/usr/local/lib/python3.9/site-packages/sqlalchemy/engine/base.py", line 1620, in _execute_20
    return meth(self, args_10style, kwargs_10style, execution_options)
  File "/usr/local/lib/python3.9/site-packages/sqlalchemy/sql/elements.py", line 325, in _execute_on_connection
    return connection._execute_clauseelement(
  File "/usr/local/lib/python3.9/site-packages/sqlalchemy/engine/base.py", line 1487, in _execute_clauseelement
    ret = self._execute_context(
  File "/usr/local/lib/python3.9/site-packages/sqlalchemy/engine/base.py", line 1851, in _execute_context
    self._handle_dbapi_exception(
  File "/usr/local/lib/python3.9/site-packages/sqlalchemy/engine/base.py", line 2032, in _handle_dbapi_exception
    util.raise_(
  File "/usr/local/lib/python3.9/site-packages/sqlalchemy/util/compat.py", line 207, in raise_
    raise exception
  File "/usr/local/lib/python3.9/site-packages/sqlalchemy/engine/base.py", line 1808, in _execute_context
    self.dialect.do_execute(
  File "/usr/local/lib/python3.9/site-packages/sqlalchemy/engine/default.py", line 732, in do_execute
    cursor.execute(statement, parameters)
  File "/usr/local/lib/python3.9/site-packages/pymysql/cursors.py", line 148, in execute
    result = self._query(query)
  File "/usr/local/lib/python3.9/site-packages/pymysql/cursors.py", line 310, in _query
    conn.query(q)
  File "/usr/local/lib/python3.9/site-packages/pymysql/connections.py", line 548, in query
    self._affected_rows = self._read_query_result(unbuffered=unbuffered)
  File "/usr/local/lib/python3.9/site-packages/pymysql/connections.py", line 775, in _read_query_result
    result.read()
  File "/usr/local/lib/python3.9/site-packages/pymysql/connections.py", line 1156, in read
    first_packet = self.connection._read_packet()
  File "/usr/local/lib/python3.9/site-packages/pymysql/connections.py", line 725, in _read_packet
    packet.raise_for_error()
  File "/usr/local/lib/python3.9/site-packages/pymysql/protocol.py", line 221, in raise_for_error
    err.raise_mysql_exception(self._data)
  File "/usr/local/lib/python3.9/site-packages/pymysql/err.py", line 143, in raise_mysql_exception
    raise errorclass(errno, errval)
sqlalchemy.exc.IntegrityError: (pymysql.err.IntegrityError) (1062, "Duplicate entry 'Testing@dtswiss.com' for key 'ix_user_email'")
[SQL: INSERT INTO user (username, email, password_hash, about_me, last_seen, token, token_expiration) VALUES (%(username)s, %(email)s, %(password_hash)s, %(about_me)s, %(last_seen)s, %(token)s, %(token_expiration)s)]
[parameters: {'username': 'TestingUser', 'email': 'Testing@dtswiss.com', 'password_hash': 'pbkdf2:sha256:260000$oUuwlM6XfnTSp8c9$e7b61a765dc686994ceab07d3209a5dcd4a621e5caf3043c36e8dbb23db647f8', 'about_me': None, 'last_seen': datetime.datetime(2022, 9, 7, 11, 30, 30, 112865), 'token': None, 'token_expiration': None}]
(Background on this error at: https://sqlalche.me/e/14/gkpj)
